[32m2023-03-31 17:41:10 +0000[0m - dagster - [34mDEBUG[0m - __ASSET_JOB - 345dc93f-b0c0-479d-b2a4-6c68f13446b7 - 17821 - LOGS_CAPTURED - Started capturing logs in process (pid: 17821).
[32m2023-03-31 17:41:11 +0000[0m - dagster - [34mDEBUG[0m - __ASSET_JOB - 345dc93f-b0c0-479d-b2a4-6c68f13446b7 - 17821 - hacker_news - STEP_START - Started execution of step "hacker_news".
[32m2023-03-31 17:41:11 +0000[0m - dagster - [34mDEBUG[0m - __ASSET_JOB - 345dc93f-b0c0-479d-b2a4-6c68f13446b7 - 17821 - hacker_news - STEP_OUTPUT - Yielded output "result" of type "Any". (Type check passed).
[32m2023-03-31 17:41:11 +0000[0m - dagster - [34mERROR[0m - [31m__ASSET_JOB - 345dc93f-b0c0-479d-b2a4-6c68f13446b7 - 17821 - hacker_news - STEP_FAILURE - Execution of step "hacker_news" failed.

dagster._core.errors.DagsterExecutionHandleOutputError: Error occurred while handling output "result" of step "hacker_news"::

AttributeError: 'OutputContext' object has no attribute 'file_manager'

Stack Trace:
  File "/home/vscode/.local/lib/python3.11/site-packages/dagster/_core/execution/plan/utils.py", line 54, in op_execution_error_boundary
    yield
  File "/home/vscode/.local/lib/python3.11/site-packages/dagster/_utils/__init__.py", line 439, in iterate_with_context
    next_output = next(iterator)
                  ^^^^^^^^^^^^^^
  File "/home/vscode/.local/lib/python3.11/site-packages/dagster/_core/execution/plan/execute_step.py", line 594, in _gen_fn
    gen_output = output_manager.handle_output(output_context, output.value)
                 ^^^^^^^^^^^^^^^^^^^^^^^^^^^^^^^^^^^^^^^^^^^^^^^^^^^^^^^^^^
  File "/workspaces/glowing-octo-engine/example_files/example_files/assets.py", line 35, in handle_output
    with context.file_manager.writeable_file_object(context) as handle:
         ^^^^^^^^^^^^^^^^^^^^
[0m
