[32m2023-03-31 17:52:30 +0000[0m - dagster - [34mDEBUG[0m - __ASSET_JOB - 81e51236-243a-4b3b-857d-57b196f9a26e - 31537 - LOGS_CAPTURED - Started capturing logs in process (pid: 31537).
[32m2023-03-31 17:52:30 +0000[0m - dagster - [34mDEBUG[0m - __ASSET_JOB - 81e51236-243a-4b3b-857d-57b196f9a26e - 31537 - hacker_news - STEP_START - Started execution of step "hacker_news".
[32m2023-03-31 17:52:31 +0000[0m - dagster - [34mDEBUG[0m - __ASSET_JOB - 81e51236-243a-4b3b-857d-57b196f9a26e - 31537 - hacker_news - STEP_OUTPUT - Yielded output "result" of type "Any". (Type check passed).
[32m2023-03-31 17:52:32 +0000[0m - dagster - [34mERROR[0m - [31m__ASSET_JOB - 81e51236-243a-4b3b-857d-57b196f9a26e - 31537 - hacker_news - STEP_FAILURE - Execution of step "hacker_news" failed.

dagster._core.errors.DagsterExecutionHandleOutputError: Error occurred while handling output "result" of step "hacker_news"::

botocore.exceptions.EndpointConnectionError: Could not connect to the endpoint URL: "http://localhost:9001/raw/s3/news_data.json"

Stack Trace:
  File "/home/vscode/.local/lib/python3.11/site-packages/dagster/_core/execution/plan/utils.py", line 54, in op_execution_error_boundary
    yield
  File "/home/vscode/.local/lib/python3.11/site-packages/dagster/_utils/__init__.py", line 439, in iterate_with_context
    next_output = next(iterator)
                  ^^^^^^^^^^^^^^
  File "/home/vscode/.local/lib/python3.11/site-packages/dagster/_core/execution/plan/execute_step.py", line 594, in _gen_fn
    gen_output = output_manager.handle_output(output_context, output.value)
                 ^^^^^^^^^^^^^^^^^^^^^^^^^^^^^^^^^^^^^^^^^^^^^^^^^^^^^^^^^^
  File "/workspaces/glowing-octo-engine/example_files/example_files/assets.py", line 37, in handle_output
    s3.put_object(
  File "/home/vscode/.local/lib/python3.11/site-packages/botocore/client.py", line 530, in _api_call
    return self._make_api_call(operation_name, kwargs)
           ^^^^^^^^^^^^^^^^^^^^^^^^^^^^^^^^^^^^^^^^^^^
  File "/home/vscode/.local/lib/python3.11/site-packages/botocore/client.py", line 943, in _make_api_call
    http, parsed_response = self._make_request(
                            ^^^^^^^^^^^^^^^^^^^
  File "/home/vscode/.local/lib/python3.11/site-packages/botocore/client.py", line 966, in _make_request
    return self._endpoint.make_request(operation_model, request_dict)
           ^^^^^^^^^^^^^^^^^^^^^^^^^^^^^^^^^^^^^^^^^^^^^^^^^^^^^^^^^^
  File "/home/vscode/.local/lib/python3.11/site-packages/botocore/endpoint.py", line 119, in make_request
    return self._send_request(request_dict, operation_model)
           ^^^^^^^^^^^^^^^^^^^^^^^^^^^^^^^^^^^^^^^^^^^^^^^^^
  File "/home/vscode/.local/lib/python3.11/site-packages/botocore/endpoint.py", line 202, in _send_request
    while self._needs_retry(
          ^^^^^^^^^^^^^^^^^^
  File "/home/vscode/.local/lib/python3.11/site-packages/botocore/endpoint.py", line 354, in _needs_retry
    responses = self._event_emitter.emit(
                ^^^^^^^^^^^^^^^^^^^^^^^^^
  File "/home/vscode/.local/lib/python3.11/site-packages/botocore/hooks.py", line 412, in emit
    return self._emitter.emit(aliased_event_name, **kwargs)
           ^^^^^^^^^^^^^^^^^^^^^^^^^^^^^^^^^^^^^^^^^^^^^^^^
  File "/home/vscode/.local/lib/python3.11/site-packages/botocore/hooks.py", line 256, in emit
    return self._emit(event_name, kwargs)
           ^^^^^^^^^^^^^^^^^^^^^^^^^^^^^^
  File "/home/vscode/.local/lib/python3.11/site-packages/botocore/hooks.py", line 239, in _emit
    response = handler(**kwargs)
               ^^^^^^^^^^^^^^^^^
  File "/home/vscode/.local/lib/python3.11/site-packages/botocore/retryhandler.py", line 207, in __call__
    if self._checker(**checker_kwargs):
       ^^^^^^^^^^^^^^^^^^^^^^^^^^^^^^^
  File "/home/vscode/.local/lib/python3.11/site-packages/botocore/retryhandler.py", line 284, in __call__
    should_retry = self._should_retry(
                   ^^^^^^^^^^^^^^^^^^^
  File "/home/vscode/.local/lib/python3.11/site-packages/botocore/retryhandler.py", line 320, in _should_retry
    return self._checker(attempt_number, response, caught_exception)
           ^^^^^^^^^^^^^^^^^^^^^^^^^^^^^^^^^^^^^^^^^^^^^^^^^^^^^^^^^
  File "/home/vscode/.local/lib/python3.11/site-packages/botocore/retryhandler.py", line 363, in __call__
    checker_response = checker(
                       ^^^^^^^^
  File "/home/vscode/.local/lib/python3.11/site-packages/botocore/retryhandler.py", line 247, in __call__
    return self._check_caught_exception(
           ^^^^^^^^^^^^^^^^^^^^^^^^^^^^^
  File "/home/vscode/.local/lib/python3.11/site-packages/botocore/retryhandler.py", line 416, in _check_caught_exception
    raise caught_exception
  File "/home/vscode/.local/lib/python3.11/site-packages/botocore/endpoint.py", line 281, in _do_get_response
    http_response = self._send(request)
                    ^^^^^^^^^^^^^^^^^^^
  File "/home/vscode/.local/lib/python3.11/site-packages/botocore/endpoint.py", line 377, in _send
    return self.http_session.send(request)
           ^^^^^^^^^^^^^^^^^^^^^^^^^^^^^^^
  File "/home/vscode/.local/lib/python3.11/site-packages/botocore/httpsession.py", line 484, in send
    raise EndpointConnectionError(endpoint_url=request.url, error=e)

The above exception occurred during handling of the following exception:
urllib3.exceptions.NewConnectionError: <botocore.awsrequest.AWSHTTPConnection object at 0x7fb671bac910>: Failed to establish a new connection: [Errno 111] Connection refused

Stack Trace:
  File "/home/vscode/.local/lib/python3.11/site-packages/botocore/httpsession.py", line 455, in send
    urllib_response = conn.urlopen(
                      ^^^^^^^^^^^^^
  File "/home/vscode/.local/lib/python3.11/site-packages/urllib3/connectionpool.py", line 787, in urlopen
    retries = retries.increment(
              ^^^^^^^^^^^^^^^^^^
  File "/home/vscode/.local/lib/python3.11/site-packages/urllib3/util/retry.py", line 525, in increment
    raise six.reraise(type(error), error, _stacktrace)
          ^^^^^^^^^^^^^^^^^^^^^^^^^^^^^^^^^^^^^^^^^^^^
  File "/home/vscode/.local/lib/python3.11/site-packages/urllib3/packages/six.py", line 770, in reraise
    raise value
  File "/home/vscode/.local/lib/python3.11/site-packages/urllib3/connectionpool.py", line 703, in urlopen
    httplib_response = self._make_request(
                       ^^^^^^^^^^^^^^^^^^^
  File "/home/vscode/.local/lib/python3.11/site-packages/urllib3/connectionpool.py", line 398, in _make_request
    conn.request(method, url, **httplib_request_kw)
  File "/home/vscode/.local/lib/python3.11/site-packages/urllib3/connection.py", line 244, in request
    super(HTTPConnection, self).request(method, url, body=body, headers=headers)
  File "/usr/local/lib/python3.11/http/client.py", line 1282, in request
    self._send_request(method, url, body, headers, encode_chunked)
  File "/home/vscode/.local/lib/python3.11/site-packages/botocore/awsrequest.py", line 94, in _send_request
    rval = super()._send_request(
           ^^^^^^^^^^^^^^^^^^^^^^
  File "/usr/local/lib/python3.11/http/client.py", line 1328, in _send_request
    self.endheaders(body, encode_chunked=encode_chunked)
  File "/usr/local/lib/python3.11/http/client.py", line 1277, in endheaders
    self._send_output(message_body, encode_chunked=encode_chunked)
  File "/home/vscode/.local/lib/python3.11/site-packages/botocore/awsrequest.py", line 123, in _send_output
    self.send(msg)
  File "/home/vscode/.local/lib/python3.11/site-packages/botocore/awsrequest.py", line 218, in send
    return super().send(str)
           ^^^^^^^^^^^^^^^^^
  File "/usr/local/lib/python3.11/http/client.py", line 975, in send
    self.connect()
  File "/home/vscode/.local/lib/python3.11/site-packages/urllib3/connection.py", line 205, in connect
    conn = self._new_conn()
           ^^^^^^^^^^^^^^^^
  File "/home/vscode/.local/lib/python3.11/site-packages/urllib3/connection.py", line 186, in _new_conn
    raise NewConnectionError(

The above exception occurred during handling of the following exception:
ConnectionRefusedError: [Errno 111] Connection refused

Stack Trace:
  File "/home/vscode/.local/lib/python3.11/site-packages/urllib3/connection.py", line 174, in _new_conn
    conn = connection.create_connection(
           ^^^^^^^^^^^^^^^^^^^^^^^^^^^^^
  File "/home/vscode/.local/lib/python3.11/site-packages/urllib3/util/connection.py", line 95, in create_connection
    raise err
  File "/home/vscode/.local/lib/python3.11/site-packages/urllib3/util/connection.py", line 85, in create_connection
    sock.connect(sa)
[0m
